[2025-09-11T03:42:43.014+0000] {taskinstance.py:1159} INFO - Dependencies all met for dep_context=non-requeueable deps ti=<TaskInstance: spark_streaming_dag.run_streaming scheduled__2025-09-11T03:41:00+00:00 [queued]>
[2025-09-11T03:42:43.029+0000] {taskinstance.py:1159} INFO - Dependencies all met for dep_context=requeueable deps ti=<TaskInstance: spark_streaming_dag.run_streaming scheduled__2025-09-11T03:41:00+00:00 [queued]>
[2025-09-11T03:42:43.030+0000] {taskinstance.py:1361} INFO - Starting attempt 1 of 2
[2025-09-11T03:42:43.048+0000] {taskinstance.py:1382} INFO - Executing <Task(PythonOperator): run_streaming> on 2025-09-11 03:41:00+00:00
[2025-09-11T03:42:43.054+0000] {standard_task_runner.py:57} INFO - Started process 1699 to run task
[2025-09-11T03:42:43.061+0000] {standard_task_runner.py:84} INFO - Running: ['***', 'tasks', 'run', 'spark_streaming_dag', 'run_streaming', 'scheduled__2025-09-11T03:41:00+00:00', '--job-id', '38', '--raw', '--subdir', 'DAGS_FOLDER/streaming_dag.py', '--cfg-path', '/tmp/tmpbz6k84hd']
[2025-09-11T03:42:43.064+0000] {standard_task_runner.py:85} INFO - Job 38: Subtask run_streaming
[2025-09-11T03:42:43.128+0000] {task_command.py:416} INFO - Running <TaskInstance: spark_streaming_dag.run_streaming scheduled__2025-09-11T03:41:00+00:00 [running]> on host 954b9572d0b9
[2025-09-11T03:42:43.286+0000] {taskinstance.py:1662} INFO - Exporting env vars: AIRFLOW_CTX_DAG_OWNER='***' AIRFLOW_CTX_DAG_ID='spark_streaming_dag' AIRFLOW_CTX_TASK_ID='run_streaming' AIRFLOW_CTX_EXECUTION_DATE='2025-09-11T03:41:00+00:00' AIRFLOW_CTX_TRY_NUMBER='1' AIRFLOW_CTX_DAG_RUN_ID='scheduled__2025-09-11T03:41:00+00:00'
[2025-09-11T03:42:54.896+0000] {spark_utils.py:25} INFO - Spark connection created successfully!
[2025-09-11T03:42:57.838+0000] {spark_utils.py:43} INFO - kafka dataframe created successfully
[2025-09-11T03:42:58.342+0000] {data_processing.py:49} INFO - Schema applied and JSON parsed.
[2025-09-11T03:42:58.381+0000] {data_processing.py:53} INFO - Dropped records with null id, email, or registered_date.
[2025-09-11T03:42:58.445+0000] {data_processing.py:61} INFO - Applied business rule validation.
[2025-09-11T03:42:58.466+0000] {data_processing.py:65} INFO - Deduplicated based on id.
[2025-09-11T03:42:58.484+0000] {cassandra_utils.py:15} WARNING - Cluster.__init__ called with contact_points specified, but no load_balancing_policy. In the next major version, this will raise an error; please specify a load-balancing policy. (contact_points = ['cassandra'], lbp = None)
[2025-09-11T03:42:58.515+0000] {cassandra_utils.py:16} WARNING - Downgrading core protocol version from 66 to 65 for 172.18.0.5:9042. To avoid this, it is best practice to explicitly set Cluster(protocol_version) to the version supported by your cluster. http://datastax.github.io/python-driver/api/cassandra/cluster.html#cassandra.cluster.Cluster.protocol_version
[2025-09-11T03:42:58.518+0000] {cassandra_utils.py:16} WARNING - Downgrading core protocol version from 65 to 5 for 172.18.0.5:9042. To avoid this, it is best practice to explicitly set Cluster(protocol_version) to the version supported by your cluster. http://datastax.github.io/python-driver/api/cassandra/cluster.html#cassandra.cluster.Cluster.protocol_version
[2025-09-11T03:42:58.559+0000] {policies.py:289} INFO - Using datacenter 'datacenter1' for DCAwareRoundRobinPolicy (via host '172.18.0.5:9042'); if incorrect, please specify a local_dc to the constructor, or limit contact points to local cluster nodes
[2025-09-11T03:42:58.619+0000] {cassandra_utils.py:18} INFO - Connected to Cassandra!
[2025-09-11T03:42:58.629+0000] {logging_mixin.py:154} INFO - Keyspace created successfully!
[2025-09-11T03:42:58.634+0000] {logging_mixin.py:154} INFO - Table created successfully!
[2025-09-11T03:42:58.635+0000] {run_streaming.py:30} INFO - Streaming is being started...
[2025-09-11T03:43:28.626+0000] {thread.py:58} WARNING - Host 172.18.0.5:9042 has been marked down
[2025-09-11T03:43:32.023+0000] {thread.py:58} WARNING - [control connection] Error connecting to 172.18.0.5:9042:
Traceback (most recent call last):
  File "cassandra/cluster.py", line 3577, in cassandra.cluster.ControlConnection._reconnect_internal
  File "cassandra/cluster.py", line 3599, in cassandra.cluster.ControlConnection._try_connect
  File "cassandra/cluster.py", line 1670, in cassandra.cluster.Cluster.connection_factory
  File "cassandra/connection.py", line 846, in cassandra.connection.Connection.factory
  File "/home/airflow/.local/lib/python3.11/site-packages/cassandra/io/libevreactor.py", line 266, in __init__
    self._connect_socket()
  File "cassandra/connection.py", line 951, in cassandra.connection.Connection._connect_socket
OSError: [Errno 113] Tried connecting to [('172.18.0.5', 9042)]. Last error: No route to host
[2025-09-11T03:43:32.026+0000] {thread.py:58} WARNING - Error attempting to reconnect to 172.18.0.5:9042, scheduling retry in 2.2 seconds: [Errno 113] Tried connecting to [('172.18.0.5', 9042)]. Last error: No route to host
[2025-09-11T03:43:36.952+0000] {thread.py:58} WARNING - Error attempting to reconnect to 172.18.0.5:9042, scheduling retry in 3.96 seconds: [Errno 113] Tried connecting to [('172.18.0.5', 9042)]. Last error: No route to host
[2025-09-11T03:43:37.436+0000] {local_task_job_runner.py:294} WARNING - State of this instance has been externally set to failed. Terminating instance.
[2025-09-11T03:43:37.441+0000] {process_utils.py:131} INFO - Sending 15 to group 1699. PIDs of all processes in the group: [1700, 1699]
[2025-09-11T03:43:37.442+0000] {process_utils.py:86} INFO - Sending the signal 15 to group 1699
[2025-09-11T03:43:37.442+0000] {taskinstance.py:1632} ERROR - Received SIGTERM. Terminating subprocesses.
[2025-09-11T03:43:37.443+0000] {clientserver.py:538} INFO - Error while receiving.
Traceback (most recent call last):
  File "/home/airflow/.local/lib/python3.11/site-packages/py4j/clientserver.py", line 511, in send_command
    answer = smart_decode(self.stream.readline()[:-1])
                          ^^^^^^^^^^^^^^^^^^^^^^
  File "/usr/local/lib/python3.11/socket.py", line 706, in readinto
    return self._sock.recv_into(b)
           ^^^^^^^^^^^^^^^^^^^^^^^
  File "/home/airflow/.local/lib/python3.11/site-packages/airflow/models/taskinstance.py", line 1634, in signal_handler
    raise AirflowException("Task received SIGTERM signal")
airflow.exceptions.AirflowException: Task received SIGTERM signal
[2025-09-11T03:43:37.453+0000] {clientserver.py:543} INFO - Closing down clientserver connection
[2025-09-11T03:43:37.454+0000] {java_gateway.py:1055} ERROR - Exception while sending command.
Traceback (most recent call last):
  File "/home/airflow/.local/lib/python3.11/site-packages/py4j/clientserver.py", line 511, in send_command
    answer = smart_decode(self.stream.readline()[:-1])
                          ^^^^^^^^^^^^^^^^^^^^^^
  File "/usr/local/lib/python3.11/socket.py", line 706, in readinto
    return self._sock.recv_into(b)
           ^^^^^^^^^^^^^^^^^^^^^^^
  File "/home/airflow/.local/lib/python3.11/site-packages/airflow/models/taskinstance.py", line 1634, in signal_handler
    raise AirflowException("Task received SIGTERM signal")
airflow.exceptions.AirflowException: Task received SIGTERM signal

During handling of the above exception, another exception occurred:

Traceback (most recent call last):
  File "/home/airflow/.local/lib/python3.11/site-packages/py4j/java_gateway.py", line 1038, in send_command
    response = connection.send_command(command)
               ^^^^^^^^^^^^^^^^^^^^^^^^^^^^^^^^
  File "/home/airflow/.local/lib/python3.11/site-packages/py4j/clientserver.py", line 539, in send_command
    raise Py4JNetworkError(
py4j.protocol.Py4JNetworkError: Error while sending or receiving
[2025-09-11T03:43:37.459+0000] {clientserver.py:543} INFO - Closing down clientserver connection
[2025-09-11T03:43:37.460+0000] {run_streaming.py:51} ERROR - Streaming job failed: An error occurred while calling o83.stop
Traceback (most recent call last):
  File "/opt/airflow/dags/spark_job/run_streaming.py", line 47, in run_streaming
    streaming_query.stop()
  File "/home/airflow/.local/lib/python3.11/site-packages/pyspark/sql/streaming/query.py", line 372, in stop
    self._jsq.stop()
  File "/home/airflow/.local/lib/python3.11/site-packages/py4j/java_gateway.py", line 1322, in __call__
    return_value = get_return_value(
                   ^^^^^^^^^^^^^^^^^
  File "/home/airflow/.local/lib/python3.11/site-packages/pyspark/errors/exceptions/captured.py", line 179, in deco
    return f(*a, **kw)
           ^^^^^^^^^^^
  File "/home/airflow/.local/lib/python3.11/site-packages/py4j/protocol.py", line 334, in get_return_value
    raise Py4JError(
py4j.protocol.Py4JError: An error occurred while calling o83.stop
[2025-09-11T03:43:37.468+0000] {python.py:194} INFO - Done. Returned value was: None
[2025-09-11T03:43:37.490+0000] {taskinstance.py:1400} INFO - Marking task as SUCCESS. dag_id=spark_streaming_dag, task_id=run_streaming, execution_date=20250911T034100, start_date=20250911T034243, end_date=20250911T034337
[2025-09-11T03:43:37.955+0000] {process_utils.py:79} INFO - Process psutil.Process(pid=1699, status='terminated', exitcode=0, started='03:42:42') (1699) terminated with exit code 0
[2025-09-11T03:43:38.021+0000] {process_utils.py:79} INFO - Process psutil.Process(pid=1700, status='terminated', started='03:42:42') (1700) terminated with exit code None
